<?xml version="1.0" ?>
<!-- =================================================================================== -->
<!-- |    This document was autogenerated by xacro from model.urdf.xacro               | -->
<!-- |    EDITING THIS FILE BY HAND IS NOT RECOMMENDED                                 | -->
<!-- =================================================================================== -->
<robot name="example_robot">
	<link name="link0_passive">
		<visual>
			<material name="blue">
				<color rgba="0 0 .8 1"/>
			</material>
			<geometry>
				<origin xyz="0 0 0" rpy="0 0 0"/>
				<cylinder length="0.0" radius="0.0"/>
			</geometry>
		</visual>
	</link>
	<link name="link0_x_axis">
		<visual>
			<material name="red">
				<color rgba="1 0 0 1"/>
			</material>
			<geometry>
				<origin xyz="0 0 0" rpy="0 0 0"/>
				<cylinder length="0.0" radius="0.0"/>
			</geometry>
		</visual>
	</link>
	<joint name="q0_x" type="fixed">
		<origin xyz="0 0 0" rpy="0 1.571 0"/>
		<parent link="link0_passive"/>
		<child link="link0_x_axis"/>
	</joint>
	<link name="link1"/>
	<link name="link1_x_axis">
		<visual>
			<origin xyz="0 0 0.25" rpy="0 0 0"/>
			<material name="red"/>
			<geometry>
				<cylinder length="0.5" radius="0.05"/>
			</geometry>
		</visual>
	</link>
	<joint name="q1" type="revolute">
		<origin xyz="0 0 0" rpy="0 0 0"/>
		<parent link="link0_passive"/>
		<child link="link1"/>
		<axis xyz="0 0 1"/>
	</joint>
	<joint name="q1_passive" type="fixed">
		<origin xyz="0 0 0" rpy="0 0 0"/>
		<parent link="link1"/>
		<child link="link1_passive"/>
	</joint>
	<link name="link1_passive">
		<visual>
			<origin xyz="0 0 0.25" rpy="0 0 0"/>
			<material name="blue"/>
			<geometry>
				<cylinder length="0.5" radius="0.05"/>
			</geometry>
		</visual>
	</link>
	<joint name="q1_x" type="fixed">
		<origin xyz="0 0 0" rpy="0 1.571 0"/>
		<parent link="link1_passive"/>
		<child link="link1_x_axis"/>
	</joint>
	<link name="link2"/>
	<link name="link2_x_axis">
		<visual>
			<origin xyz="0 0 0.25" rpy="0 0 0"/>
			<material name="red"/>
			<geometry>
				<cylinder length="0.5" radius="0.05"/>
			</geometry>
		</visual>
	</link>
	<joint name="q2" type="revolute">
		<origin xyz="0 0 1.5707963267948966" rpy="0 0 0"/>
		<parent link="link1_passive"/>
		<child link="link2"/>
		<axis xyz="0 0 1"/>
	</joint>
	<joint name="q2_passive" type="fixed">
		<origin xyz="0.2 0 0" rpy="3.141592653589793 0 0"/>
		<parent link="link2"/>
		<child link="link2_passive"/>
	</joint>
	<link name="link2_passive">
		<visual>
			<origin xyz="0 0 0.25" rpy="0 0 0"/>
			<material name="blue"/>
			<geometry>
				<cylinder length="0.5" radius="0.05"/>
			</geometry>
		</visual>
	</link>
	<joint name="q2_x" type="fixed">
		<origin xyz="0 0 0" rpy="0 1.571 0"/>
		<parent link="link2_passive"/>
		<child link="link2_x_axis"/>
	</joint>
	<link name="link3"/>
	<link name="link3_x_axis">
		<visual>
			<origin xyz="0 0 0.25" rpy="0 0 0"/>
			<material name="red"/>
			<geometry>
				<cylinder length="0.5" radius="0.05"/>
			</geometry>
		</visual>
	</link>
	<joint name="q3" type="revolute">
		<origin xyz="0 0 1.5707963267948966" rpy="0 0 0"/>
		<parent link="link2_passive"/>
		<child link="link3"/>
		<axis xyz="0 0 1"/>
	</joint>
	<joint name="q3_passive" type="fixed">
		<origin xyz="0.2 0 0" rpy="3.141592653589793 0 0"/>
		<parent link="link3"/>
		<child link="link3_passive"/>
	</joint>
	<link name="link3_passive">
		<visual>
			<origin xyz="0 0 0.25" rpy="0 0 0"/>
			<material name="blue"/>
			<geometry>
				<cylinder length="0.5" radius="0.05"/>
			</geometry>
		</visual>
	</link>
	<joint name="q3_x" type="fixed">
		<origin xyz="0 0 0" rpy="0 1.571 0"/>
		<parent link="link3_passive"/>
		<child link="link3_x_axis"/>
	</joint>
	<link name="link4"/>
	<link name="link4_x_axis">
		<visual>
			<origin xyz="0 0 0.25" rpy="0 0 0"/>
			<material name="red"/>
			<geometry>
				<cylinder length="0.5" radius="0.05"/>
			</geometry>
		</visual>
	</link>
	<joint name="q4" type="revolute">
		<origin xyz="0 0 0" rpy="0 0 0"/>
		<parent link="link3_passive"/>
		<child link="link4"/>
		<axis xyz="0 0 1"/>
	</joint>
	<joint name="q4_passive" type="fixed">
		<origin xyz="0.6 0 0" rpy="0 0 0"/>
		<parent link="link4"/>
		<child link="link4_passive"/>
	</joint>
	<link name="link4_passive">
		<visual>
			<origin xyz="0 0 0.25" rpy="0 0 0"/>
			<material name="blue"/>
			<geometry>
				<cylinder length="0.5" radius="0.05"/>
			</geometry>
		</visual>
	</link>
	<joint name="q4_x" type="fixed">
		<origin xyz="0 0 0" rpy="0 1.571 0"/>
		<parent link="link4_passive"/>
		<child link="link4_x_axis"/>
	</joint>
	<link name="link5"/>
	<link name="link5_x_axis">
		<visual>
			<origin xyz="0 0 0.25" rpy="0 0 0"/>
			<material name="red"/>
			<geometry>
				<cylinder length="0.5" radius="0.05"/>
			</geometry>
		</visual>
	</link>
	<joint name="q5" type="revolute">
		<origin xyz="0 0 1.5707963267948966" rpy="0 0 0"/>
		<parent link="link4_passive"/>
		<child link="link5"/>
		<axis xyz="0 0 1"/>
	</joint>
	<joint name="q5_passive" type="fixed">
		<origin xyz="0.1 0 0" rpy="3.141592653589793 0 0"/>
		<parent link="link5"/>
		<child link="link5_passive"/>
	</joint>
	<link name="link5_passive">
		<visual>
			<origin xyz="0 0 0.25" rpy="0 0 0"/>
			<material name="blue"/>
			<geometry>
				<cylinder length="0.5" radius="0.05"/>
			</geometry>
		</visual>
	</link>
	<joint name="q5_x" type="fixed">
		<origin xyz="0 0 0" rpy="0 1.571 0"/>
		<parent link="link5_passive"/>
		<child link="link5_x_axis"/>
	</joint>
	<link name="link6"/>
	<link name="link6_x_axis">
		<visual>
			<origin xyz="0 0 0.25" rpy="0 0 0"/>
			<material name="red"/>
			<geometry>
				<cylinder length="0.5" radius="0.05"/>
			</geometry>
		</visual>
	</link>
	<joint name="q6" type="revolute">
		<origin xyz="0 0 1.5707963267948966" rpy="0 0 0"/>
		<parent link="link5_passive"/>
		<child link="link6"/>
		<axis xyz="0 0 1"/>
	</joint>
	<joint name="q6_passive" type="fixed">
		<origin xyz="0.2 0 0" rpy="3.141592653589793 0 0"/>
		<parent link="link6"/>
		<child link="link6_passive"/>
	</joint>
	<link name="link6_passive">
		<visual>
			<origin xyz="0 0 0.25" rpy="0 0 0"/>
			<material name="blue"/>
			<geometry>
				<cylinder length="0.5" radius="0.05"/>
			</geometry>
		</visual>
	</link>
	<joint name="q6_x" type="fixed">
		<origin xyz="0 0 0" rpy="0 1.571 0"/>
		<parent link="link6_passive"/>
		<child link="link6_x_axis"/>
	</joint>
	<link name="link7"/>
	<link name="link7_x_axis">
		<visual>
			<origin xyz="0 0 0.25" rpy="0 0 0"/>
			<material name="red"/>
			<geometry>
				<cylinder length="0.5" radius="0.05"/>
			</geometry>
		</visual>
	</link>
	<joint name="q7" type="revolute">
		<origin xyz="0 0 0" rpy="0 0 0"/>
		<parent link="link6_passive"/>
		<child link="link7"/>
		<axis xyz="0 0 1"/>
	</joint>
	<joint name="q7_passive" type="fixed">
		<origin xyz="0.6 0 0" rpy="0 0 0"/>
		<parent link="link7"/>
		<child link="link7_passive"/>
	</joint>
	<link name="link7_passive">
		<visual>
			<origin xyz="0 0 0.25" rpy="0 0 0"/>
			<material name="blue"/>
			<geometry>
				<cylinder length="0.5" radius="0.05"/>
			</geometry>
		</visual>
	</link>
	<joint name="q7_x" type="fixed">
		<origin xyz="0 0 0" rpy="0 1.571 0"/>
		<parent link="link7_passive"/>
		<child link="link7_x_axis"/>
	</joint>
	<link name="link8"/>
	<link name="link8_x_axis">
		<visual>
			<origin xyz="0 0 0.25" rpy="0 0 0"/>
			<material name="red"/>
			<geometry>
				<cylinder length="0.5" radius="0.05"/>
			</geometry>
		</visual>
	</link>
	<joint name="q8" type="revolute">
		<origin xyz="0 0 1.5707963267948966" rpy="0 0 0"/>
		<parent link="link7_passive"/>
		<child link="link8"/>
		<axis xyz="0 0 1"/>
	</joint>
	<joint name="q8_passive" type="fixed">
		<origin xyz="0.1 0 0" rpy="3.141592653589793 0 0"/>
		<parent link="link8"/>
		<child link="link8_passive"/>
	</joint>
	<link name="link8_passive">
		<visual>
			<origin xyz="0 0 0.25" rpy="0 0 0"/>
			<material name="blue"/>
			<geometry>
				<cylinder length="0.5" radius="0.05"/>
			</geometry>
		</visual>
	</link>
	<joint name="q8_x" type="fixed">
		<origin xyz="0 0 0" rpy="0 1.571 0"/>
		<parent link="link8_passive"/>
		<child link="link8_x_axis"/>
	</joint>
	<link name="link9"/>
	<link name="link9_x_axis">
		<visual>
			<origin xyz="0 0 0.25" rpy="0 0 0"/>
			<material name="red"/>
			<geometry>
				<cylinder length="0.5" radius="0.05"/>
			</geometry>
		</visual>
	</link>
	<joint name="q9" type="revolute">
		<origin xyz="0 0 1.5707963267948966" rpy="0 0 0"/>
		<parent link="link8_passive"/>
		<child link="link9"/>
		<axis xyz="0 0 1"/>
	</joint>
	<joint name="q9_passive" type="fixed">
		<origin xyz="0.2 0 0" rpy="3.141592653589793 0 0"/>
		<parent link="link9"/>
		<child link="link9_passive"/>
	</joint>
	<link name="link9_passive">
		<visual>
			<origin xyz="0 0 0.25" rpy="0 0 0"/>
			<material name="blue"/>
			<geometry>
				<cylinder length="0.5" radius="0.05"/>
			</geometry>
		</visual>
	</link>
	<joint name="q9_x" type="fixed">
		<origin xyz="0 0 0" rpy="0 1.571 0"/>
		<parent link="link9_passive"/>
		<child link="link9_x_axis"/>
	</joint>
	<link name="link10"/>
	<link name="link10_x_axis">
		<visual>
			<origin xyz="0 0 0.25" rpy="0 0 0"/>
			<material name="red"/>
			<geometry>
				<cylinder length="0.5" radius="0.05"/>
			</geometry>
		</visual>
	</link>
	<joint name="q10" type="revolute">
		<origin xyz="0 0 0" rpy="0 0 0"/>
		<parent link="link9_passive"/>
		<child link="link10"/>
		<axis xyz="0 0 1"/>
	</joint>
	<joint name="q10_passive" type="fixed">
		<origin xyz="0.6 0 0" rpy="0 0 0"/>
		<parent link="link10"/>
		<child link="link10_passive"/>
	</joint>
	<link name="link10_passive">
		<visual>
			<origin xyz="0 0 0.25" rpy="0 0 0"/>
			<material name="blue"/>
			<geometry>
				<cylinder length="0.5" radius="0.05"/>
			</geometry>
		</visual>
	</link>
	<joint name="q10_x" type="fixed">
		<origin xyz="0 0 0" rpy="0 1.571 0"/>
		<parent link="link10_passive"/>
		<child link="link10_x_axis"/>
	</joint>
	<link name="link11"/>
	<link name="link11_x_axis">
		<visual>
			<origin xyz="0 0 0.25" rpy="0 0 0"/>
			<material name="red"/>
			<geometry>
				<cylinder length="0.5" radius="0.05"/>
			</geometry>
		</visual>
	</link>
	<joint name="q11" type="revolute">
		<origin xyz="0 0 0" rpy="0 0 0"/>
		<parent link="link10_passive"/>
		<child link="link11"/>
		<axis xyz="0 0 1"/>
	</joint>
	<joint name="q11_passive" type="fixed">
		<origin xyz="2 0 0" rpy="0 0 0"/>
		<parent link="link11"/>
		<child link="link11_passive"/>
	</joint>
	<link name="link11_passive">
		<visual>
			<origin xyz="0 0 0.25" rpy="0 0 0"/>
			<material name="blue"/>
			<geometry>
				<cylinder length="0.5" radius="0.05"/>
			</geometry>
		</visual>
	</link>
	<joint name="q11_x" type="fixed">
		<origin xyz="0 0 0" rpy="0 1.571 0"/>
		<parent link="link11_passive"/>
		<child link="link11_x_axis"/>
	</joint>
	<link name="link12"/>
	<link name="link12_x_axis">
		<visual>
			<origin xyz="0 0 0.25" rpy="0 0 0"/>
			<material name="red"/>
			<geometry>
				<cylinder length="0.5" radius="0.05"/>
			</geometry>
		</visual>
	</link>
	<joint name="q12" type="revolute">
		<origin xyz="0 0 0" rpy="0 0 -0.8"/>
		<parent link="link11_passive"/>
		<child link="link12"/>
		<axis xyz="0 0 1"/>
	</joint>
	<joint name="q12_passive" type="fixed">
		<origin xyz="1 0 0" rpy="0 0 0"/>
		<parent link="link12"/>
		<child link="link12_passive"/>
	</joint>
	<link name="link12_passive">
		<visual>
			<origin xyz="0 0 0.25" rpy="0 0 0"/>
			<material name="blue"/>
			<geometry>
				<cylinder length="0.5" radius="0.05"/>
			</geometry>
		</visual>
	</link>
	<joint name="q12_x" type="fixed">
		<origin xyz="0 0 0" rpy="0 1.571 0"/>
		<parent link="link12_passive"/>
		<child link="link12_x_axis"/>
	</joint>
</robot>
